Workbook

Sheet 📊 本月摘要
B1: 📊 CB 月度異動摘要 | 115年5月
B2: 近九年(109個月) CB 創新高/新低檔數及佔比變化 | 含重大歷史事件標記
B3: 創新高 105 檔 (28.8%) | E3: 創新低 45 檔 (12.3) | 掛牌中 365 檔
B4: 月份 | C4: 掛牌檔數 | D4: 新高 | E4: 佔比% | F4: 新低 | G4: 佔比% | H4: 重大事件
B5: 115/05 | C5: 365 | D5: 105 | E5: 0.28767123 | F5: 45 | G5: 0.12328767 | H5: 本月 新高105檔
B6: 115/04 | C6: 370 | D6: 97 | E6: 0.262 | F6: 39 | G6: 0.105 | H6: 新高97檔
B7: 115/03 | C7: 374 | D7: 63 | E7: 0.168 | F7: 69 | G7: 0.184
B8: 115/02 | C8: 363 | D8: 42 | E8: 0.116 | F8: 26 | G8: 0.072
B9: 115/01 | C9: 361 | D9: 49 | E9: 0.136 | F9: 33 | G9: 0.091
B10: 114/12 | C10: 352 | D10: 42 | E10: 0.119 | F10: 25 | G10: 0.071
B11: 114/11 | C11: 350 | D11: 41 | E11: 0.117 | F11: 40 | G11: 0.114
B12: 114/10 | C12: 355 | D12: 31 | E12: 0.087 | F12: 19 | G12: 0.054
B13: 114/09 | C13: 353 | D13: 57 | E13: 0.161 | F13: 13 | G13: 0.037
B14: 114/08 | C14: 354 | D14: 48 | E14: 0.136 | F14: 25 | G14: 0.071
B15: 114/07 | C15: 344 | D15: 33 | E15: 0.096 | F15: 33 | G15: 0.096
B16: 114/06 | C16: 343 | D16: 23 | E16: 0.067 | F16: 39 | G16: 0.114
B17: 114/05 | C17: 329 | D17: 7 | E17: 0.021 | F17: 23 | G17: 0.07
B18: 114/04 | C18: 330 | D18: 2 | E18: 0.006 | F18: 197 | G18: 0.597 | H18: 📉川普關稅 新低197檔
B19: 114/03 | C19: 338 | D19: 20 | E19: 0.059 | F19: 55 | G19: 0.163
B20: 114/02 | C20: 337 | D20: 53 | E20: 0.157 | F20: 36 | G20: 0.107
B21: 114/01 | C21: 341 | D21: 16 | E21: 0.047 | F21: 54 | G21: 0.158
B22: 113/12 | C22: 342 | D22: 32 | E22: 0.094 | F22: 94 | G22: 0.275
B23: 113/11 | C23: 339 | D23: 14 | E23: 0.041 | F23: 90 | G23: 0.265
B24: 113/10 | C24: 331 | D24: 32 | E24: 0.097 | F24: 43 | G24: 0.13
B25: 113/09 | C25: 326 | D25: 48 | E25: 0.147 | F25: 33 | G25: 0.101
B26: 113/08 | C26: 321 | D26: 41 | E26: 0.128 | F26: 53 | G26: 0.165
B27: 113/07 | C27: 314 | D27: 82 | E27: 0.261 | F27: 15 | G27: 0.048
B28: 113/06 | C28: 307 | D28: 65 | E28: 0.212 | F28: 12 | G28: 0.039
B29: 113/05 | C29: 304 | D29: 68 | E29: 0.224 | F29: 14 | G29: 0.046
B30: 113/04 | C30: 296 | D30: 75 | E30: 0.253 | F30: 17 | G30: 0.057
B31: 113/03 | C31: 306 | D31: 93 | E31: 0.304 | F31: 19 | G31: 0.062 | H31: 新高93檔
B32: 113/02 | C32: 304 | D32: 83 | E32: 0.273 | F32: 16 | G32: 0.053
B33: 113/01 | C33: 310 | D33: 31 | E33: 0.1 | F33: 20 | G33: 0.065
B34: 112/12 | C34: 312 | D34: 55 | E34: 0.176 | F34: 13 | G34: 0.042
B35: 112/11 | C35: 308 | D35: 35 | E35: 0.114 | F35: 31 | G35: 0.101
B36: 112/10 | C36: 311 | D36: 25 | E36: 0.08 | F36: 23 | G36: 0.074
B37: 112/09 | C37: 316 | D37: 39 | E37: 0.123 | F37: 21 | G37: 0.066
B38: 112/08 | C38: 320 | D38: 36 | E38: 0.112 | F38: 32 | G38: 0.1
B39: 112/07 | C39: 319 | D39: 77 | E39: 0.241 | F39: 19 | G39: 0.06
B40: 112/06 | C40: 315 | D40: 66 | E40: 0.21 | F40: 10 | G40: 0.032
...

Sheet 🔴 創新高
B2: 🔴 創新高 (105 檔) | 115年5月
B3: 相較上月(4月30日),依漲跌幅排序 | 排除本月新掛牌
B5: 序 | C5: CB代號 | D5: CB名稱 | E5: 上月最高 | F5: 本月最高 | G5: 增加(元) | H5: 漲幅%
B6: 1 | C6: 61828 | D6: 合晶八 | E6: 144.95 | F6: 290 | G6: 145.05 | H6: 1.0006899
B7: 2 | C7: 80426 | D7: 金山電六 | E7: 140.5 | F7: 250 | G7: 109.5 | H7: 0.77935943
B8: 3 | C8: 62076 | D8: 雷科六 | E8: 132.95 | F8: 228 | G8: 95.05 | H8: 0.71493042
B9: 4 | C9: 62075 | D9: 雷科五 | E9: 131 | F9: 223 | G9: 92 | H9: 0.70229008
B10: 5 | C10: 62745 | D10: 台燿五 | E10: 277 | F10: 450 | G10: 173 | H10: 0.62454874
B11: 6 | C11: 80273 | D11: 鈦昇三 | E11: 265 | F11: 420 | G11: 155 | H11: 0.58490566
B12: 7 | C12: 24642 | D12: 盟立二 | E12: 148.55 | F12: 233 | G12: 84.45 | H12: 0.56849546
B13: 8 | C13: 64324 | D13: 今展科四 | E13: 140 | F13: 217 | G13: 77 | H13: 0.55
B14: 9 | C14: 31351 | D14: 凌航一 | E14: 302 | F14: 454 | G14: 152 | H14: 0.50331126
B15: 10 | C15: 33571 | D15: 臺慶科一 | E15: 185 | F15: 275 | G15: 90 | H15: 0.48648649
B16: 11 | C16: 30165 | D16: 嘉晶五 | E16: 135.75 | F16: 201 | G16: 65.25 | H16: 0.48066298
B17: 12 | C17: 30336 | D17: 威健六 | E17: 150 | F17: 222 | G17: 72 | H17: 0.48
... B110: 105 | C110: 61011 | D110: 寬魚國際一 | E110: 118 | F110: 118.1 | G110: 0.1 | H110: 0.00084745763
B112: 📊 平均 | E112: =IFERROR(AVERAGE(E6:E110),"") | F112: =IFERROR(AVERAGE(F6:F110),"") | G112: =IFERROR(AVERAGE(G6:G110),"") | H112: =IFERROR(AVERAGE(H6:H110),"")

Sheet 🟢 創新低
B2: 🟢 創新低 (45 檔) | 115年5月
B3: 相較上月(4月30日),依漲跌幅排序 | 排除本月新掛牌
B5: 序 | C5: CB代號 | D5: CB名稱 | E5: 上月最低 | F5: 本月最低 | G5: 減少(元) | H5: 跌幅%
B6: 1 | C6: 84762 | D6: 台境二 | E6: 102 | F6: 88 | G6: -14 | H6: -0.1372549
B7: 2 | C7: 64725 | D7: 保瑞五 | E7: 104.5 | F7: 92 | G7: -12.5 | H7: -0.11961722
B8: 3 | C8: 64724 | D8: 保瑞四 | E8: 102.25 | F8: 90.8 | G8: -11.45 | H8: -0.11198044
B9: 4 | C9: 35642 | D9: 其陽二 | E9: 95 | F9: 89.1 | G9: -5.9 | H9: -0.062105263
B10: 5 | C10: 68901 | D10: 來億一KY | E10: 92.75 | F10: 87.1 | G10: -5.65 | H10: -0.060916442
B11: 6 | C11: 68902 | D11: 來億二KY | E11: 90.8 | F11: 86 | G11: -4.8 | H11: -0.052863436
B12: 7 | C12: 41136 | D12: 聯上六 | E12: 89.05 | F12: 85.5 | G12: -3.55 | H12: -0.039865244
B13: 8 | C13: 37152 | D13: 定穎投控二 | E13: 130.15 | F13: 126 | G13: -4.15 | H13: -0.031886285
B14: 9 | C14: 27324 | D14: 六角四 | E14: 103.1 | F14: 100 | G14: -3.1 | H14: -0.030067895
B15: 10 | C15: 68061 | D15: 森崴能源一 | E15: 96.7 | F15: 94 | G15: -2.7 | H15: -0.027921406
B16: 11 | C16: 67962 | D16: 晉弘二 | E16: 90.55 | F16: 88.1 | G16: -2.45 | H16: -0.027056875
B17: 12 | C17: 69821 | D17: 大井泵浦一 | E17: 94 | F17: 92 | G17: -2 | H17: -0.021276596
... B50: 45 | C50: 67681 | D50: 志強一KY | E50: 101.05 | F50: 101 | G50: -0.05 | H50: -0.00049480455
B52: 📊 平均 | E52: =IFERROR(AVERAGE(E6:E50),"") | F52: =IFERROR(AVERAGE(F6:F50),"") | G52: =IFERROR(AVERAGE(G6:G50),"") | H52: =IFERROR(AVERAGE(H6:H50),"")

Sheet 🎯 一鍵查詢
B2: 🎯 CB 一鍵查詢
B3: 輸入股票代號,自動列出該公司歷年所有可轉債 ｜ 資料期間:民國93年～115年5月31日
B5: 股票代號 | C5: 2383 | D5: ← 請輸入 4 碼 股票代號 | F5: 該公司 CB 檔數 | H5: =IFERROR(COUNTIF(對應表!$B:$B,$C$5),0)
B8: 序 | C8: CB代號 | D8: CB名稱 | E8: 掛牌最高 | F8: 掛牌最低 | G8: 振幅(倍) | H8: 振幅% | I8: 區間(元) | J8: 異動 | K8: 月變化
B9: =IFERROR(IF(MATCH(1,對應表!$C$2:$C$3000,0)>0,1,""),"") | C9: =IFERROR(INDEX(對應表!$A$2:$A$3000,MATCH(1,對應表!$C$2:$C$3000,0)),"") | D9: =IFERROR(VLOOKUP(C9,CB歷年最高最低價!$A:$D,2,FALSE),"") | E9: =IFERROR(VLOOKUP(C9,CB歷年最高最低價!$A:$D,3,FALSE),"") | F9: =IFERROR(VLOOKUP(C9,CB歷年最高最低價!$A:$D,4,FALSE),"") | G9: =IFERROR(E9/F9,"") | H9: =IFERROR(E9/F9-1,"") | I9: =IFERROR(E9-F9,"") | J9: =IFERROR(IF(VLOOKUP(C9,CB歷年最高最低價!$A:$F,5,FALSE)="H","🔴新高",IF(VLOOKUP(C9,CB歷年最高最低價!$A:$F,5,FALSE)="L","🟢新低",IF(VLOOKUP(C9,CB歷年最高最低價!$A:$F,5,FALSE)="HL","🔴🟢",""))),"") | K9: =IFERROR(IF(VLOOKUP(C9,CB歷年最高最低價!$A:$F,6,FALSE)="","",VLOOKUP(C9,CB歷年最高最低價!$A:$F,6,FALSE)),"")
B10: =IFERROR(IF(MATCH(2,對應表!$C$2:$C$3000,0)>0,2,""),"") | C10: =IFERROR(INDEX(對應表!$A$2:$A$3000,MATCH(2,對應表!$C$2:$C$3000,0)),"") | D10: =IFERROR(VLOOKUP(C10,CB歷年最高最低價!$A:$D,2,FALSE),"") | E10: =IFERROR(VLOOKUP(C10,CB歷年最高最低價!$A:$D,3,FALSE),"") | F10: =IFERROR(VLOOKUP(C10,CB歷年最高最低價!$A:$D,4,FALSE),"") | G10: =IFERROR(E10/F10,"") | H10: =IFERROR(E10/F10-1,"") | I10: =IFERROR(E10-F10,"") | J10: =IFERROR(IF(VLOOKUP(C10,CB歷年最高最低價!$A:$F,5,FALSE)="H","🔴新高",IF(VLOOKUP(C10,CB歷年最高最低價!$A:$F,5,FALSE)="L","🟢新低",IF(VLOOKUP(C10,CB歷年最高最低價!$A:$F,5,FALSE)="HL","🔴🟢",""))),"") | K10: =IFERROR(IF(VLOOKUP(C10,CB歷年最高最低價!$A:$F,6,FALSE)="","",VLOOKUP(C10,CB歷年最高最低價!$A:$F,6,FALSE)),"")
B11: =IFERROR(IF(MATCH(3,對應表!$C$2:$C$3000,0)>0,3,""),"") | C11: =IFERROR(INDEX(對應表!$A$2:$A$3000,MATCH(3,對應表!$C$2:$C$3000,0)),"") | D11: =IFERROR(VLOOKUP(C11,CB歷年最高最低價!$A:$D,2,FALSE),"") | E11: =IFERROR(VLOOKUP(C11,CB歷年最高最低價!$A:$D,3,FALSE),"") | F11: =IFERROR(VLOOKUP(C11,CB歷年最高最低價!$A:$D,4,FALSE),"") | G11: =IFERROR(E11/F11,"") | H11: =IFERROR(E11/F11-1,"") | I11: =IFERROR(E11-F11,"") | J11: =IFERROR(IF(VLOOKUP(C11,CB歷年最高最低價!$A:$F,5,FALSE)="H","🔴新高",IF(VLOOKUP(C11,CB歷年最高最低價!$A:$F,5,FALSE)="L","🟢新低",IF(VLOOKUP(C11,CB歷年最高最低價!$A:$F,5,FALSE)="HL","🔴🟢",""))),"") | K11: =IFERROR(IF(VLOOKUP(C11,CB歷年最高最低價!$A:$F,6,FALSE)="","",VLOOKUP(C11,CB歷年最高最低價!$A:$F,6,FALSE)),"")
B12: =IFERROR(IF(MATCH(4,對應表!$C$2:$C$3000,0)>0,4,""),"") | C12: =IFERROR(INDEX(對應表!$A$2:$A$3000,MATCH(4,對應表!$C$2:$C$3000,0)),"") | D12: =IFERROR(VLOOKUP(C12,CB歷年最高最低價!$A:$D,2,FALSE),"") | E12: =IFERROR(VLOOKUP(C12,CB歷年最高最低價!$A:$D,3,FALSE),"") | F12: =IFERROR(VLOOKUP(C12,CB歷年最高最低價!$A:$D,4,FALSE),"") | G12: =IFERROR(E12/F12,"") | H12: =IFERROR(E12/F12-1,"") | I12: =IFERROR(E12-F12,"") | J12: =IFERROR(IF(VLOOKUP(C12,CB歷年最高最低價!$A:$F,5,FALSE)="H","🔴新高",IF(VLOOKUP(C12,CB歷年最高最低價!$A:$F,5,FALSE)="L","🟢新低",IF(VLOOKUP(C12,CB歷年最高最低價!$A:$F,5,FALSE)="HL","🔴🟢",""))),"") | K12: =IFERROR(IF(VLOOKUP(C12,CB歷年最高最低價!$A:$F,6,FALSE)="","",VLOOKUP(C12,CB歷年最高最低價!$A:$F,6,FALSE)),"")
B13: =IFERROR(IF(MATCH(5,對應表!$C$2:$C$3000,0)>0,5,""),"") | C13: =IFERROR(INDEX(對應表!$A$2:$A$3000,MATCH(5,對應表!$C$2:$C$3000,0)),"") | D13: =IFERROR(VLOOKUP(C13,CB歷年最高最低價!$A:$D,2,FALSE),"") | E13: =IFERROR(VLOOKUP(C13,CB歷年最高最低價!$A:$D,3,FALSE),"") | F13: =IFERROR(VLOOKUP(C13,CB歷年最高最低價!$A:$D,4,FALSE),"") | G13: =IFERROR(E13/F13,"") | H13: =IFERROR(E13/F13-1,"") | I13: =IFERROR(E13-F13,"") | J13: =IFERROR(IF(VLOOKUP(C13,CB歷年最高最低價!$A:$F,5,FALSE)="H","🔴新高",IF(VLOOKUP(C13,CB歷年最高最低價!$A:$F,5,FALSE)="L","🟢新低",IF(VLOOKUP(C13,CB歷年最高最低價!$A:$F,5,FALSE)="HL","🔴🟢",""))),"") | K13: =IFERROR(IF(VLOOKUP(C13,CB歷年最高最低價!$A:$F,6,FALSE)="","",VLOOKUP(C13,CB歷年最高最低價!$A:$F,6,FALSE)),"")
B14: =IFERROR(IF(MATCH(6,對應表!$C$2:$C$3000,0)>0,6,""),"") | C14: =IFERROR(INDEX(對應表!$A$2:$A$3000,MATCH(6,對應表!$C$2:$C$3000,0)),"") | D14: =IFERROR(VLOOKUP(C14,CB歷年最高最低價!$A:$D,2,FALSE),"") | E14: =IFERROR(VLOOKUP(C14,CB歷年最高最低價!$A:$D,3,FALSE),"") | F14: =IFERROR(VLOOKUP(C14,CB歷年最高最低價!$A:$D,4,FALSE),"") | G14: =IFERROR(E14/F14,"") | H14: =IFERROR(E14/F14-1,"") | I14: =IFERROR(E14-F14,"") | J14: =IFERROR(IF(VLOOKUP(C14,CB歷年最高最低價!$A:$F,5,FALSE)="H","🔴新高",IF(VLOOKUP(C14,CB歷年最高最低價!$A:$F,5,FALSE)="L","🟢新低",IF(VLOOKUP(C14,CB歷年最高最低價!$A:$F,5,FALSE)="HL","🔴🟢",""))),"") | K14: =IFERROR(IF(VLOOKUP(C14,CB歷年最高最低價!$A:$F,6,FALSE)="","",VLOOKUP(C14,CB歷年最高最低價!$A:$F,6,FALSE)),"")
B15: =IFERROR(IF(MATCH(7,對應表!$C$2:$C$3000,0)>0,7,""),"") | C15: =IFERROR(INDEX(對應表!$A$2:$A$3000,MATCH(7,對應表!$C$2:$C$3000,0)),"") | D15: =IFERROR(VLOOKUP(C15,CB歷年最高最低價!$A:$D,2,FALSE),"") | E15: =IFERROR(VLOOKUP(C15,CB歷年最高最低價!$A:$D,3,FALSE),"") | F15: =IFERROR(VLOOKUP(C15,CB歷年最高最低價!$A:$D,4,FALSE),"") | G15: =IFERROR(E15/F15,"") | H15: =IFERROR(E15/F15-1,"") | I15: =IFERROR(E15-F15,"") | J15: =IFERROR(IF(VLOOKUP(C15,CB歷年最高最低價!$A:$F,5,FALSE)="H","🔴新高",IF(VLOOKUP(C15,CB歷年最高最低價!$A:$F,5,FALSE)="L","🟢新低",IF(VLOOKUP(C15,CB歷年最高最低價!$A:$F,5,FALSE)="HL","🔴🟢",""))),"") | K15: =IFERROR(IF(VLOOKUP(C15,CB歷年最高最低價!$A:$F,6,FALSE)="","",VLOOKUP(C15,CB歷年最高最低價!$A:$F,6,FALSE)),"")
B16: =IFERROR(IF(MATCH(8,對應表!$C$2:$C$3000,0)>0,8,""),"") | C16: =IFERROR(INDEX(對應表!$A$2:$A$3000,MATCH(8,對應表!$C$2:$C$3000,0)),"") | D16: =IFERROR(VLOOKUP(C16,CB歷年最高最低價!$A:$D,2,FALSE),"") | E16: =IFERROR(VLOOKUP(C16,CB歷年最高最低價!$A:$D,3,FALSE),"") | F16: =IFERROR(VLOOKUP(C16,CB歷年最高最低價!$A:$D,4,FALSE),"") | G16: =IFERROR(E16/F16,"") | H16: =IFERROR(E16/F16-1,"") | I16: =IFERROR(E16-F16,"") | J16: =IFERROR(IF(VLOOKUP(C16,CB歷年最高最低價!$A:$F,5,FALSE)="H","🔴新高",IF(VLOOKUP(C16,CB歷年最高最低價!$A:$F,5,FALSE)="L","🟢新低",IF(VLOOKUP(C16,CB歷年最高最低價!$A:$F,5,FALSE)="HL","🔴🟢",""))),"") | K16: =IFERROR(IF(VLOOKUP(C16,CB歷年最高最低價!$A:$F,6,FALSE)="","",VLOOKUP(C16,CB歷年最高最低價!$A:$F,6,FALSE)),"")
B17: =IFERROR(IF(MATCH(9,對應表!$C$2:$C$3000,0)>0,9,""),"") | C17: =IFERROR(INDEX(對應表!$A$2:$A$3000,MATCH(9,對應表!$C$2:$C$3000,0)),"") | D17: =IFERROR(VLOOKUP(C17,CB歷年最高最低價!$A:$D,2,FALSE),"") | E17: =IFERROR(VLOOKUP(C17,CB歷年最高最低價!$A:$D,3,FALSE),"") | F17: =IFERROR(VLOOKUP(C17,CB歷年最高最低價!$A:$D,4,FALSE),"") | G17: =IFERROR(E17/F17,"") | H17: =IFERROR(E17/F17-1,"") | I17: =IFERROR(E17-F17,"") | J17: =IFERROR(IF(VLOOKUP(C17,CB歷年最高最低價!$A:$F,5,FALSE)="H","🔴新高",IF(VLOOKUP(C17,CB歷年最高最低價!$A:$F,5,FALSE)="L","🟢新低",IF(VLOOKUP(C17,CB歷年最高最低價!$A:$F,5,FALSE)="HL","🔴🟢",""))),"") | K17: =IFERROR(IF(VLOOKUP(C17,CB歷年最高最低價!$A:$F,6,FALSE)="","",VLOOKUP(C17,CB歷年最高最低價!$A:$F,6,FALSE)),"")
B18: =IFERROR(IF(MATCH(10,對應表!$C$2:$C$3000,0)>0,10,""),"") | C18: =IFERROR(INDEX(對應表!$A$2:$A$3000,MATCH(10,對應表!$C$2:$C$3000,0)),"") | D18: =IFERROR(VLOOKUP(C18,CB歷年最高最低價!$A:$D,2,FALSE),"") | E18: =IFERROR(VLOOKUP(C18,CB歷年最高最低價!$A:$D,3,FALSE),"") | F18: =IFERROR(VLOOKUP(C18,CB歷年最高最低價!$A:$D,4,FALSE),"") | G18: =IFERROR(E18/F18,"") | H18: =IFERROR(E18/F18-1,"") | I18: =IFERROR(E18-F18,"") | J18: =IFERROR(IF(VLOOKUP(C18,CB歷年最高最低價!$A:$F,5,FALSE)="H","🔴新高",IF(VLOOKUP(C18,CB歷年最高最低價!$A:$F,5,FALSE)="L","🟢新低",IF(VLOOKUP(C18,CB歷年最高最低價!$A:$F,5,FALSE)="HL","🔴🟢",""))),"") | K18: =IFERROR(IF(VLOOKUP(C18,CB歷年最高最低價!$A:$F,6,FALSE)="","",VLOOKUP(C18,CB歷年最高最低價!$A:$F,6,FALSE)),"")
B19: =IFERROR(IF(MATCH(11,對應表!$C$2:$C$3000,0)>0,11,""),"") | C19: =IFERROR(INDEX(對應表!$A$2:$A$3000,MATCH(11,對應表!$C$2:$C$3000,0)),"") | D19: =IFERROR(VLOOKUP(C19,CB歷年最高最低價!$A:$D,2,FALSE),"") | E19: =IFERROR(VLOOKUP(C19,CB歷年最高最低價!$A:$D,3,FALSE),"") | F19: =IFERROR(VLOOKUP(C19,CB歷年最高最低價!$A:$D,4,FALSE),"") | G19: =IFERROR(E19/F19,"") | H19: =IFERROR(E19/F19-1,"") | I19: =IFERROR(E19-F19,"") | J19: =IFERROR(IF(VLOOKUP(C19,CB歷年最高最低價!$A:$F,5,FALSE)="H","🔴新高",IF(VLOOKUP(C19,CB歷年最高最低價!$A:$F,5,FALSE)="L","🟢新低",IF(VLOOKUP(C19,CB歷年最高最低價!$A:$F,5,FALSE)="HL","🔴🟢",""))),"") | K19: =IFERROR(IF(VLOOKUP(C19,CB歷年最高最低價!$A:$F,6,FALSE)="","",VLOOKUP(C19,CB歷年最高最低價!$A:$F,6,FALSE)),"")
B20: =IFERROR(IF(MATCH(12,對應表!$C$2:$C$3000,0)>0,12,""),"") | C20: =IFERROR(INDEX(對應表!$A$2:$A$3000,MATCH(12,對應表!$C$2:$C$3000,0)),"") | D20: =IFERROR(VLOOKUP(C20,CB歷年最高最低價!$A:$D,2,FALSE),"") | E20: =IFERROR(VLOOKUP(C20,CB歷年最高最低價!$A:$D,3,FALSE),"") | F20: =IFERROR(VLOOKUP(C20,CB歷年最高最低價!$A:$D,4,FALSE),"") | G20: =IFERROR(E20/F20,"") | H20: =IFERROR(E20/F20-1,"") | I20: =IFERROR(E20-F20,"") | J20: =IFERROR(IF(VLOOKUP(C20,CB歷年最高最低價!$A:$F,5,FALSE)="H","🔴新高",IF(VLOOKUP(C20,CB歷年最高最低價!$A:$F,5,FALSE)="L","🟢新低",IF(VLOOKUP(C20,CB歷年最高最低價!$A:$F,5,FALSE)="HL","🔴🟢",""))),"") | K20: =IFERROR(IF(VLOOKUP(C20,CB歷年最高最低價!$A:$F,6,FALSE)="","",VLOOKUP(C20,CB歷年最高最低價!$A:$F,6,FALSE)),"")
B21: =IFERROR(IF(MATCH(13,對應表!$C$2:$C$3000,0)>0,13,""),"") | C21: =IFERROR(INDEX(對應表!$A$2:$A$3000,MATCH(13,對應表!$C$2:$C$3000,0)),"") | D21: =IFERROR(VLOOKUP(C21,CB歷年最高最低價!$A:$D,2,FALSE),"") | E21: =IFERROR(VLOOKUP(C21,CB歷年最高最低價!$A:$D,3,FALSE),"") | F21: =IFERROR(VLOOKUP(C21,CB歷年最高最低價!$A:$D,4,FALSE),"") | G21: =IFERROR(E21/F21,"") | H21: =IFERROR(E21/F21-1,"") | I21: =IFERROR(E21-F21,"") | J21: =IFERROR(IF(VLOOKUP(C21,CB歷年最高最低價!$A:$F,5,FALSE)="H","🔴新高",IF(VLOOKUP(C21,CB歷年最高最低價!$A:$F,5,FALSE)="L","🟢新低",IF(VLOOKUP(C21,CB歷年最高最低價!$A:$F,5,FALSE)="HL","🔴🟢",""))),"") | K21: =IFERROR(IF(VLOOKUP(C21,CB歷年最高最低價!$A:$F,6,FALSE)="","",VLOOKUP(C21,CB歷年最高最低價!$A:$F,6,FALSE)),"")
B22: =IFERROR(IF(MATCH(14,對應表!$C$2:$C$3000,0)>0,14,""),"") | C22: =IFERROR(INDEX(對應表!$A$2:$A$3000,MATCH(14,對應表!$C$2:$C$3000,0)),"") | D22: =IFERROR(VLOOKUP(C22,CB歷年最高最低價!$A:$D,2,FALSE),"") | E22: =IFERROR(VLOOKUP(C22,CB歷年最高最低價!$A:$D,3,FALSE),"") | F22: =IFERROR(VLOOKUP(C22,CB歷年最高最低價!$A:$D,4,FALSE),"") | G22: =IFERROR(E22/F22,"") | H22: =IFERROR(E22/F22-1,"") | I22: =IFERROR(E22-F22,"") | J22: =IFERROR(IF(VLOOKUP(C22,CB歷年最高最低價!$A:$F,5,FALSE)="H","🔴新高",IF(VLOOKUP(C22,CB歷年最高最低價!$A:$F,5,FALSE)="L","🟢新低",IF(VLOOKUP(C22,CB歷年最高最低價!$A:$F,5,FALSE)="HL","🔴🟢",""))),"") | K22: =IFERROR(IF(VLOOKUP(C22,CB歷年最高最低價!$A:$F,6,FALSE)="","",VLOOKUP(C22,CB歷年最高最低價!$A:$F,6,FALSE)),"")
B23: =IFERROR(IF(MATCH(15,對應表!$C$2:$C$3000,0)>0,15,""),"") | C23: =IFERROR(INDEX(對應表!$A$2:$A$3000,MATCH(15,對應表!$C$2:$C$3000,0)),"") | D23: =IFERROR(VLOOKUP(C23,CB歷年最高最低價!$A:$D,2,FALSE),"") | E23: =IFERROR(VLOOKUP(C23,CB歷年最高最低價!$A:$D,3,FALSE),"") | F23: =IFERROR(VLOOKUP(C23,CB歷年最高最低價!$A:$D,4,FALSE),"") | G23: =IFERROR(E23/F23,"") | H23: =IFERROR(E23/F23-1,"") | I23: =IFERROR(E23-F23,"") | J23: =IFERROR(IF(VLOOKUP(C23,CB歷年最高最低價!$A:$F,5,FALSE)="H","🔴新高",IF(VLOOKUP(C23,CB歷年最高最低價!$A:$F,5,FALSE)="L","🟢新低",IF(VLOOKUP(C23,CB歷年最高最低價!$A:$F,5,FALSE)="HL","🔴🟢",""))),"") | K23: =IFERROR(IF(VLOOKUP(C23,CB歷年最高最低價!$A:$F,6,FALSE)="","",VLOOKUP(C23,CB歷年最高最低價!$A:$F,6,FALSE)),"")
B24: =IFERROR(IF(MATCH(16,對應表!$C$2:$C$3000,0)>0,16,""),"") | C24: =IFERROR(INDEX(對應表!$A$2:$A$3000,MATCH(16,對應表!$C$2:$C$3000,0)),"") | D24: =IFERROR(VLOOKUP(C24,CB歷年最高最低價!$A:$D,2,FALSE),"") | E24: =IFERROR(VLOOKUP(C24,CB歷年最高最低價!$A:$D,3,FALSE),"") | F24: =IFERROR(VLOOKUP(C24,CB歷年最高最低價!$A:$D,4,FALSE),"") | G24: =IFERROR(E24/F24,"") | H24: =IFERROR(E24/F24-1,"") | I24: =IFERROR(E24-F24,"") | J24: =IFERROR(IF(VLOOKUP(C24,CB歷年最高最低價!$A:$F,5,FALSE)="H","🔴新高",IF(VLOOKUP(C24,CB歷年最高最低價!$A:$F,5,FALSE)="L","🟢新低",IF(VLOOKUP(C24,CB歷年最高最低價!$A:$F,5,FALSE)="HL","🔴🟢",""))),"") | K24: =IFERROR(IF(VLOOKUP(C24,CB歷年最高最低價!$A:$F,6,FALSE)="","",VLOOKUP(C24,CB歷年最高最低價!$A:$F,6,FALSE)),"")
B25: =IFERROR(IF(MATCH(17,對應表!$C$2:$C$3000,0)>0,17,""),"") | C25: =IFERROR(INDEX(對應表!$A$2:$A$3000,MATCH(17,對應表!$C$2:$C$3000,0)),"") | D25: =IFERROR(VLOOKUP(C25,CB歷年最高最低價!$A:$D,2,FALSE),"") | E25: =IFERROR(VLOOKUP(C25,CB歷年最高最低價!$A:$D,3,FALSE),"") | F25: =IFERROR(VLOOKUP(C25,CB歷年最高最低價!$A:$D,4,FALSE),"") | G25: =IFERROR(E25/F25,"") | H25: =IFERROR(E25/F25-1,"") | I25: =IFERROR(E25-F25,"") | J25: =IFERROR(IF(VLOOKUP(C25,CB歷年最高最低價!$A:$F,5,FALSE)="H","🔴新高",IF(VLOOKUP(C25,CB歷年最高最低價!$A:$F,5,FALSE)="L","🟢新低",IF(VLOOKUP(C25,CB歷年最高最低價!$A:$F,5,FALSE)="HL","🔴🟢",""))),"") | K25: =IFERROR(IF(VLOOKUP(C25,CB歷年最高最低價!$A:$F,6,FALSE)="","",VLOOKUP(C25,CB歷年最高最低價!$A:$F,6,FALSE)),"")
B26: =IFERROR(IF(MATCH(18,對應表!$C$2:$C$3000,0)>0,18,""),"") | C26: =IFERROR(INDEX(對應表!$A$2:$A$3000,MATCH(18,對應表!$C$2:$C$3000,0)),"") | D26: =IFERROR(VLOOKUP(C26,CB歷年最高最低價!$A:$D,2,FALSE),"") | E26: =IFERROR(VLOOKUP(C26,CB歷年最高最低價!$A:$D,3,FALSE),"") | F26: =IFERROR(VLOOKUP(C26,CB歷年最高最低價!$A:$D,4,FALSE),"") | G26: =IFERROR(E26/F26,"") | H26: =IFERROR(E26/F26-1,"") | I26: =IFERROR(E26-F26,"") | J26: =IFERROR(IF(VLOOKUP(C26,CB歷年最高最低價!$A:$F,5,FALSE)="H","🔴新高",IF(VLOOKUP(C26,CB歷年最高最低價!$A:$F,5,FALSE)="L","🟢新低",IF(VLOOKUP(C26,CB歷年最高最低價!$A:$F,5,FALSE)="HL","🔴🟢",""))),"") | K26: =IFERROR(IF(VLOOKUP(C26,CB歷年最高最低價!$A:$F,6,FALSE)="","",VLOOKUP(C26,CB歷年最高最低價!$A:$F,6,FALSE)),"")
B27: =IFERROR(IF(MATCH(19,對應表!$C$2:$C$3000,0)>0,19,""),"") | C27: =IFERROR(INDEX(對應表!$A$2:$A$3000,MATCH(19,對應表!$C$2:$C$3000,0)),"") | D27: =IFERROR(VLOOKUP(C27,CB歷年最高最低價!$A:$D,2,FALSE),"") | E27: =IFERROR(VLOOKUP(C27,CB歷年最高最低價!$A:$D,3,FALSE),"") | F27: =IFERROR(VLOOKUP(C27,CB歷年最高最低價!$A:$D,4,FALSE),"") | G27: =IFERROR(E27/F27,"") | H27: =IFERROR(E27/F27-1,"") | I27: =IFERROR(E27-F27,"") | J27: =IFERROR(IF(VLOOKUP(C27,CB歷年最高最低價!$A:$F,5,FALSE)="H","🔴新高",IF(VLOOKUP(C27,CB歷年最高最低價!$A:$F,5,FALSE)="L","🟢新低",IF(VLOOKUP(C27,CB歷年最高最低價!$A:$F,5,FALSE)="HL","🔴🟢",""))),"") | K27: =IFERROR(IF(VLOOKUP(C27,CB歷年最高最低價!$A:$F,6,FALSE)="","",VLOOKUP(C27,CB歷年最高最低價!$A:$F,6,FALSE)),"")
B28: =IFERROR(IF(MATCH(20,對應表!$C$2:$C$3000,0)>0,20,""),"") | C28: =IFERROR(INDEX(對應表!$A$2:$A$3000,MATCH(20,對應表!$C$2:$C$3000,0)),"") | D28: =IFERROR(VLOOKUP(C28,CB歷年最高最低價!$A:$D,2,FALSE),"") | E28: =IFERROR(VLOOKUP(C28,CB歷年最高最低價!$A:$D,3,FALSE),"") | F28: =IFERROR(VLOOKUP(C28,CB歷年最高最低價!$A:$D,4,FALSE),"") | G28: =IFERROR(E28/F28,"") | H28: =IFERROR(E28/F28-1,"") | I28: =IFERROR(E28-F28,"") | J28: =IFERROR(IF(VLOOKUP(C28,CB歷年最高最低價!$A:$F,5,FALSE)="H","🔴新高",IF(VLOOKUP(C28,CB歷年最高最低價!$A:$F,5,FALSE)="L","🟢新低",IF(VLOOKUP(C28,CB歷年最高最低價!$A:$F,5,FALSE)="HL","🔴🟢",""))),"") | K28: =IFERROR(IF(VLOOKUP(C28,CB歷年最高最低價!$A:$F,6,FALSE)="","",VLOOKUP(C28,CB歷年最高最低價!$A:$F,6,FALSE)),"")
B29: 📊 平均值 | E29: =IFERROR(AVERAGE(E9:E28),"") | F29: =IFERROR(AVERAGE(F9:F28),"") | G29: =IFERROR(AVERAGE(G9:G28),"") | H29: =IFERROR(AVERAGE(H9:H28),"") | I29: =IFERROR(AVERAGE(I9:I28),"")
B30: 🔝 歷史最高 | E30: =IFERROR(MAX(E9:E28),"") | F30: =IFERROR(MAX(F9:F28),"") | G30: =IFERROR(MAX(G9:G28),"") | H30: =IFERROR(MAX(H9:H28),"") | I30: =IFERROR(MAX(I9:I28),"")
B31: 🔻 歷史最低 | E31: =IFERROR(MIN(E9:E28),"") | F31: =IFERROR(MIN(F9:F28),"") | G31: =IFERROR(MIN(G9:G28),"") | H31: =IFERROR(MIN(H9:H28),"") | I31: =IFERROR(MIN(I9:I28),"")
B33: 📌 使用說明
B34: 1. 在上方黃色格輸入 4 碼股票代號(例如 2383 台光電、2308 台達電)
B35: 2. 系統自動列出該公司歷年發行的所有可轉債,最多 20 檔
B36: 3. 振幅(倍) = 掛牌最高 ÷ 掛牌最低,可看出該檔 CB 的歷史波動能量
B37: 4. 下方統計列自動彙總:平均、歷史最高、歷史最低
B38: ⚠️ 本工具僅供歷史資料參考,不構成任何投資建議

Sheet 🔧 DIY 自組查詢
B2: 🔧 DIY 自組查詢 | 跨公司多檔 CB 並列比較
B3: 在 C 欄黃色區輸入 CB 代號,可跨公司自由組合最多 50 檔
B5: 序 | C5: CB代號 | D5: CB名稱 | E5: 股票代號 | F5: 掛牌最高 | G5: 掛牌最低 | H5: 振幅(倍) | I5: 振幅% | J5: 區間(元) | K5: 異動 | L5: 月變化
B6: 1 | C6: 23831 | D6: =IFERROR(VLOOKUP(C6,CB歷年最高最低價!$A:$D,2,FALSE),"") | E6: =IFERROR(VLOOKUP(C6,對應表!$A:$B,2,FALSE),"") | F6: =IFERROR(VLOOKUP(C6,CB歷年最高最低價!$A:$D,3,FALSE),"") | G6: =IFERROR(VLOOKUP(C6,CB歷年最高最低價!$A:$D,4,FALSE),"") | H6: =IFERROR(F6/G6,"") | I6: =IFERROR(F6/G6-1,"") | J6: =IFERROR(F6-G6,"") | K6: =IFERROR(IF(VLOOKUP(C6,CB歷年最高最低價!$A:$F,5,FALSE)="H","🔴新高",IF(VLOOKUP(C6,CB歷年最高最低價!$A:$F,5,FALSE)="L","🟢新低",IF(VLOOKUP(C6,CB歷年最高最低價!$A:$F,5,FALSE)="HL","🔴🟢",""))),"") | L6: =IFERROR(IF(VLOOKUP(C6,CB歷年最高最低價!$A:$F,6,FALSE)="","",VLOOKUP(C6,CB歷年最高最低價!$A:$F,6,FALSE)),"")
B7: 2 | C7: 23832 | D7: =IFERROR(VLOOKUP(C7,CB歷年最高最低價!$A:$D,2,FALSE),"") | E7: =IFERROR(VLOOKUP(C7,對應表!$A:$B,2,FALSE),"") | F7: =IFERROR(VLOOKUP(C7,CB歷年最高最低價!$A:$D,3,FALSE),"") | G7: =IFERROR(VLOOKUP(C7,CB歷年最高最低價!$A:$D,4,FALSE),"") | H7: =IFERROR(F7/G7,"") | I7: =IFERROR(F7/G7-1,"") | J7: =IFERROR(F7-G7,"") | K7: =IFERROR(IF(VLOOKUP(C7,CB歷年最高最低價!$A:$F,5,FALSE)="H","🔴新高",IF(VLOOKUP(C7,CB歷年最高最低價!$A:$F,5,FALSE)="L","🟢新低",IF(VLOOKUP(C7,CB歷年最高最低價!$A:$F,5,FALSE)="HL","🔴🟢",""))),"") | L7: =IFERROR(IF(VLOOKUP(C7,CB歷年最高最低價!$A:$F,6,FALSE)="","",VLOOKUP(C7,CB歷年最高最低價!$A:$F,6,FALSE)),"")
B8: 3 | C8: 23833 | D8: =IFERROR(VLOOKUP(C8,CB歷年最高最低價!$A:$D,2,FALSE),"") | E8: =IFERROR(VLOOKUP(C8,對應表!$A:$B,2,FALSE),"") | F8: =IFERROR(VLOOKUP(C8,CB歷年最高最低價!$A:$D,3,FALSE),"") | G8: =IFERROR(VLOOKUP(C8,CB歷年最高最低價!$A:$D,4,FALSE),"") | H8: =IFERROR(F8/G8,"") | I8: =IFERROR(F8/G8-1,"") | J8: =IFERROR(F8-G8,"") | K8: =IFERROR(IF(VLOOKUP(C8,CB歷年最高最低價!$A:$F,5,FALSE)="H","🔴新高",IF(VLOOKUP(C8,CB歷年最高最低價!$A:$F,5,FALSE)="L","🟢新低",IF(VLOOKUP(C8,CB歷年最高最低價!$A:$F,5,FALSE)="HL","🔴🟢",""))),"") | L8: =IFERROR(IF(VLOOKUP(C8,CB歷年最高最低價!$A:$F,6,FALSE)="","",VLOOKUP(C8,CB歷年最高最低價!$A:$F,6,FALSE)),"")
B9: 4 | C9: 23834 | D9: =IFERROR(VLOOKUP(C9,CB歷年最高最低價!$A:$D,2,FALSE),"") | E9: =IFERROR(VLOOKUP(C9,對應表!$A:$B,2,FALSE),"") | F9: =IFERROR(VLOOKUP(C9,CB歷年最高最低價!$A:$D,3,FALSE),"") | G9: =IFERROR(VLOOKUP(C9,CB歷年最高最低價!$A:$D,4,FALSE),"") | H9: =IFERROR(F9/G9,"") | I9: =IFERROR(F9/G9-1,"") | J9: =IFERROR(F9-G9,"") | K9: =IFERROR(IF(VLOOKUP(C9,CB歷年最高最低價!$A:$F,5,FALSE)="H","🔴新高",IF(VLOOKUP(C9,CB歷年最高最低價!$A:$F,5,FALSE)="L","🟢新低",IF(VLOOKUP(C9,CB歷年最高最低價!$A:$F,5,FALSE)="HL","🔴🟢",""))),"") | L9: =IFERROR(IF(VLOOKUP(C9,CB歷年最高最低價!$A:$F,6,FALSE)="","",VLOOKUP(C9,CB歷年最高最低價!$A:$F,6,FALSE)),"")
B10: 5 | C10: 23835 | D10: =IFERROR(VLOOKUP(C10,CB歷年最高最低價!$A:$D,2,FALSE),"") | E10: =IFERROR(VLOOKUP(C10,對應表!$A:$B,2,FALSE),"") | F10: =IFERROR(VLOOKUP(C10,CB歷年最高最低價!$A:$D,3,FALSE),"") | G10: =IFERROR(VLOOKUP(C10,CB歷年最高最低價!$A:$D,4,FALSE),"") | H10: =IFERROR(F10/G10,"") | I10: =IFERROR(F10/G10-1,"") | J10: =IFERROR(F10-G10,"") | K10: =IFERROR(IF(VLOOKUP(C10,CB歷年最高最低價!$A:$F,5,FALSE)="H","🔴新高",IF(VLOOKUP(C10,CB歷年最高最低價!$A:$F,5,FALSE)="L","🟢新低",IF(VLOOKUP(C10,CB歷年最高最低價!$A:$F,5,FALSE)="HL","🔴🟢",""))),"") | L10: =IFERROR(IF(VLOOKUP(C10,CB歷年最高最低價!$A:$F,6,FALSE)="","",VLOOKUP(C10,CB歷年最高最低價!$A:$F,6,FALSE)),"")
B11: 6 | C11: 23836 | D11: =IFERROR(VLOOKUP(C11,CB歷年最高最低價!$A:$D,2,FALSE),"") | E11: =IFERROR(VLOOKUP(C11,對應表!$A:$B,2,FALSE),"") | F11: =IFERROR(VLOOKUP(C11,CB歷年最高最低價!$A:$D,3,FALSE),"") | G11: =IFERROR(VLOOKUP(C11,CB歷年最高最低價!$A:$D,4,FALSE),"") | H11: =IFERROR(F11/G11,"") | I11: =IFERROR(F11/G11-1,"") | J11: =IFERROR(F11-G11,"") | K11: =IFERROR(IF(VLOOKUP(C11,CB歷年最高最低價!$A:$F,5,FALSE)="H","🔴新高",IF(VLOOKUP(C11,CB歷年最高最低價!$A:$F,5,FALSE)="L","🟢新低",IF(VLOOKUP(C11,CB歷年最高最低價!$A:$F,5,FALSE)="HL","🔴🟢",""))),"") | L11: =IFERROR(IF(VLOOKUP(C11,CB歷年最高最低價!$A:$F,6,FALSE)="","",VLOOKUP(C11,CB歷年最高最低價!$A:$F,6,FALSE)),"")
B12: 7 | C12: 23837 | D12: =IFERROR(VLOOKUP(C12,CB歷年最高最低價!$A:$D,2,FALSE),"") | E12: =IFERROR(VLOOKUP(C12,對應表!$A:$B,2,FALSE),"") | F12: =IFERROR(VLOOKUP(C12,CB歷年最高最低價!$A:$D,3,FALSE),"") | G12: =IFERROR(VLOOKUP(C12,CB歷年最高最低價!$A:$D,4,FALSE),"") | H12: =IFERROR(F12/G12,"") | I12: =IFERROR(F12/G12-1,"") | J12: =IFERROR(F12-G12,"") | K12: =IFERROR(IF(VLOOKUP(C12,CB歷年最高最低價!$A:$F,5,FALSE)="H","🔴新高",IF(VLOOKUP(C12,CB歷年最高最低價!$A:$F,5,FALSE)="L","🟢新低",IF(VLOOKUP(C12,CB歷年最高最低價!$A:$F,5,FALSE)="HL","🔴🟢",""))),"") | L12: =IFERROR(IF(VLOOKUP(C12,CB歷年最高最低價!$A:$F,6,FALSE)="","",VLOOKUP(C12,CB歷年最高最低價!$A:$F,6,FALSE)),"")
B13: 8 | D13: =IFERROR(VLOOKUP(C13,CB歷年最高最低價!$A:$D,2,FALSE),"") | E13: =IFERROR(VLOOKUP(C13,對應表!$A:$B,2,FALSE),"") | F13: =IFERROR(VLOOKUP(C13,CB歷年最高最低價!$A:$D,3,FALSE),"") | G13: =IFERROR(VLOOKUP(C13,CB歷年最高最低價!$A:$D,4,FALSE),"") | H13: =IFERROR(F13/G13,"") | I13: =IFERROR(F13/G13-1,"") | J13: =IFERROR(F13-G13,"") | K13: =IFERROR(IF(VLOOKUP(C13,CB歷年最高最低價!$A:$F,5,FALSE)="H","🔴新高",IF(VLOOKUP(C13,CB歷年最高最低價!$A:$F,5,FALSE)="L","🟢新低",IF(VLOOKUP(C13,CB歷年最高最低價!$A:$F,5,FALSE)="HL","🔴🟢",""))),"") | L13: =IFERROR(IF(VLOOKUP(C13,CB歷年最高最低價!$A:$F,6,FALSE)="","",VLOOKUP(C13,CB歷年最高最低價!$A:$F,6,FALSE)),"")
B14: 9 | D14: =IFERROR(VLOOKUP(C14,CB歷年最高最低價!$A:$D,2,FALSE),"") | E14: =IFERROR(VLOOKUP(C14,對應表!$A:$B,2,FALSE),"") | F14: =IFERROR(VLOOKUP(C14,CB歷年最高最低價!$A:$D,3,FALSE),"") | G14: =IFERROR(VLOOKUP(C14,CB歷年最高最低價!$A:$D,4,FALSE),"") | H14: =IFERROR(F14/G14,"") | I14: =IFERROR(F14/G14-1,"") | J14: =IFERROR(F14-G14,"") | K14: =IFERROR(IF(VLOOKUP(C14,CB歷年最高最低價!$A:$F,5,FALSE)="H","🔴新高",IF(VLOOKUP(C14,CB歷年最高最低價!$A:$F,5,FALSE)="L","🟢新低",IF(VLOOKUP(C14,CB歷年最高最低價!$A:$F,5,FALSE)="HL","🔴🟢",""))),"") | L14: =IFERROR(IF(VLOOKUP(C14,CB歷年最高最低價!$A:$F,6,FALSE)="","",VLOOKUP(C14,CB歷年最高最低價!$A:$F,6,FALSE)),"")
B15: 10 | D15: =IFERROR(VLOOKUP(C15,CB歷年最高最低價!$A:$D,2,FALSE),"") | E15: =IFERROR(VLOOKUP(C15,對應表!$A:$B,2,FALSE),"") | F15: =IFERROR(VLOOKUP(C15,CB歷年最高最低價!$A:$D,3,FALSE),"") | G15: =IFERROR(VLOOKUP(C15,CB歷年最高最低價!$A:$D,4,FALSE),"") | H15: =IFERROR(F15/G15,"") | I15: =IFERROR(F15/G15-1,"") | J15: =IFERROR(F15-G15,"") | K15: =IFERROR(IF(VLOOKUP(C15,CB歷年最高最低價!$A:$F,5,FALSE)="H","🔴新高",IF(VLOOKUP(C15,CB歷年最高最低價!$A:$F,5,FALSE)="L","🟢新低",IF(VLOOKUP(C15,CB歷年最高最低價!$A:$F,5,FALSE)="HL","🔴🟢",""))),"") | L15: =IFERROR(IF(VLOOKUP(C15,CB歷年最高最低價!$A:$F,6,FALSE)="","",VLOOKUP(C15,CB歷年最高最低價!$A:$F,6,FALSE)),"")
B16: 11 | D16: =IFERROR(VLOOKUP(C16,CB歷年最高最低價!$A:$D,2,FALSE),"") | E16: =IFERROR(VLOOKUP(C16,對應表!$A:$B,2,FALSE),"") | F16: =IFERROR(VLOOKUP(C16,CB歷年最高最低價!$A:$D,3,FALSE),"") | G16: =IFERROR(VLOOKUP(C16,CB歷年最高最低價!$A:$D,4,FALSE),"") | H16: =IFERROR(F16/G16,"") | I16: =IFERROR(F16/G16-1,"") | J16: =IFERROR(F16-G16,"") | K16: =IFERROR(IF(VLOOKUP(C16,CB歷年最高最低價!$A:$F,5,FALSE)="H","🔴新高",IF(VLOOKUP(C16,CB歷年最高最低價!$A:$F,5,FALSE)="L","🟢新低",IF(VLOOKUP(C16,CB歷年最高最低價!$A:$F,5,FALSE)="HL","🔴🟢",""))),"") | L16: =IFERROR(IF(VLOOKUP(C16,CB歷年最高最低價!$A:$F,6,FALSE)="","",VLOOKUP(C16,CB歷年最高最低價!$A:$F,6,FALSE)),"")
B17: 12 | D17: =IFERROR(VLOOKUP(C17,CB歷年最高最低價!$A:$D,2,FALSE),"") | E17: =IFERROR(VLOOKUP(C17,對應表!$A:$B,2,FALSE),"") | F17: =IFERROR(VLOOKUP(C17,CB歷年最高最低價!$A:$D,3,FALSE),"") | G17: =IFERROR(VLOOKUP(C17,CB歷年最高最低價!$A:$D,4,FALSE),"") | H17: =IFERROR(F17/G17,"") | I17: =IFERROR(F17/G17-1,"") | J17: =IFERROR(F17-G17,"") | K17: =IFERROR(IF(VLOOKUP(C17,CB歷年最高最低價!$A:$F,5,FALSE)="H","🔴新高",IF(VLOOKUP(C17,CB歷年最高最低價!$A:$F,5,FALSE)="L","🟢新低",IF(VLOOKUP(C17,CB歷年最高最低價!$A:$F,5,FALSE)="HL","🔴🟢",""))),"") | L17: =IFERROR(IF(VLOOKUP(C17,CB歷年最高最低價!$A:$F,6,FALSE)="","",VLOOKUP(C17,CB歷年最高最低價!$A:$F,6,FALSE)),"")
B18: 13 | D18: =IFERROR(VLOOKUP(C18,CB歷年最高最低價!$A:$D,2,FALSE),"") | E18: =IFERROR(VLOOKUP(C18,對應表!$A:$B,2,FALSE),"") | F18: =IFERROR(VLOOKUP(C18,CB歷年最高最低價!$A:$D,3,FALSE),"") | G18: =IFERROR(VLOOKUP(C18,CB歷年最高最低價!$A:$D,4,FALSE),"") | H18: =IFERROR(F18/G18,"") | I18: =IFERROR(F18/G18-1,"") | J18: =IFERROR(F18-G18,"") | K18: =IFERROR(IF(VLOOKUP(C18,CB歷年最高最低價!$A:$F,5,FALSE)="H","🔴新高",IF(VLOOKUP(C18,CB歷年最高最低價!$A:$F,5,FALSE)="L","🟢新低",IF(VLOOKUP(C18,CB歷年最高最低價!$A:$F,5,FALSE)="HL","🔴🟢",""))),"") | L18: =IFERROR(IF(VLOOKUP(C18,CB歷年最高最低價!$A:$F,6,FALSE)="","",VLOOKUP(C18,CB歷年最高最低價!$A:$F,6,FALSE)),"")
B19: 14 | D19: =IFERROR(VLOOKUP(C19,CB歷年最高最低價!$A:$D,2,FALSE),"") | E19: =IFERROR(VLOOKUP(C19,對應表!$A:$B,2,FALSE),"") | F19: =IFERROR(VLOOKUP(C19,CB歷年最高最低價!$A:$D,3,FALSE),"") | G19: =IFERROR(VLOOKUP(C19,CB歷年最高最低價!$A:$D,4,FALSE),"") | H19: =IFERROR(F19/G19,"") | I19: =IFERROR(F19/G19-1,"") | J19: =IFERROR(F19-G19,"") | K19: =IFERROR(IF(VLOOKUP(C19,CB歷年最高最低價!$A:$F,5,FALSE)="H","🔴新高",IF(VLOOKUP(C19,CB歷年最高最低價!$A:$F,5,FALSE)="L","🟢新低",IF(VLOOKUP(C19,CB歷年最高最低價!$A:$F,5,FALSE)="HL","🔴🟢",""))),"") | L19: =IFERROR(IF(VLOOKUP(C19,CB歷年最高最低價!$A:$F,6,FALSE)="","",VLOOKUP(C19,CB歷年最高最低價!$A:$F,6,FALSE)),"")
B20: 15 | D20: =IFERROR(VLOOKUP(C20,CB歷年最高最低價!$A:$D,2,FALSE),"") | E20: =IFERROR(VLOOKUP(C20,對應表!$A:$B,2,FALSE),"") | F20: =IFERROR(VLOOKUP(C20,CB歷年最高最低價!$A:$D,3,FALSE),"") | G20: =IFERROR(VLOOKUP(C20,CB歷年最高最低價!$A:$D,4,FALSE),"") | H20: =IFERROR(F20/G20,"") | I20: =IFERROR(F20/G20-1,"") | J20: =IFERROR(F20-G20,"") | K20: =IFERROR(IF(VLOOKUP(C20,CB歷年最高最低價!$A:$F,5,FALSE)="H","🔴新高",IF(VLOOKUP(C20,CB歷年最高最低價!$A:$F,5,FALSE)="L","🟢新低",IF(VLOOKUP(C20,CB歷年最高最低價!$A:$F,5,FALSE)="HL","🔴🟢",""))),"") | L20: =IFERROR(IF(VLOOKUP(C20,CB歷年最高最低價!$A:$F,6,FALSE)="","",VLOOKUP(C20,CB歷年最高最低價!$A:$F,6,FALSE)),"")
B21: 16 | D21: =IFERROR(VLOOKUP(C21,CB歷年最高最低價!$A:$D,2,FALSE),"") | E21: =IFERROR(VLOOKUP(C21,對應表!$A:$B,2,FALSE),"") | F21: =IFERROR(VLOOKUP(C21,CB歷年最高最低價!$A:$D,3,FALSE),"") | G21: =IFERROR(VLOOKUP(C21,CB歷年最高最低價!$A:$D,4,FALSE),"") | H21: =IFERROR(F21/G21,"") | I21: =IFERROR(F21/G21-1,"") | J21: =IFERROR(F21-G21,"") | K21: =IFERROR(IF(VLOOKUP(C21,CB歷年最高最低價!$A:$F,5,FALSE)="H","🔴新高",IF(VLOOKUP(C21,CB歷年最高最低價!$A:$F,5,FALSE)="L","🟢新低",IF(VLOOKUP(C21,CB歷年最高最低價!$A:$F,5,FALSE)="HL","🔴🟢",""))),"") | L21: =IFERROR(IF(VLOOKUP(C21,CB歷年最高最低價!$A:$F,6,FALSE)="","",VLOOKUP(C21,CB歷年最高最低價!$A:$F,6,FALSE)),"")
B22: 17 | D22: =IFERROR(VLOOKUP(C22,CB歷年最高最低價!$A:$D,2,FALSE),"") | E22: =IFERROR(VLOOKUP(C22,對應表!$A:$B,2,FALSE),"") | F22: =IFERROR(VLOOKUP(C22,CB歷年最高最低價!$A:$D,3,FALSE),"") | G22: =IFERROR(VLOOKUP(C22,CB歷年最高最低價!$A:$D,4,FALSE),"") | H22: =IFERROR(F22/G22,"") | I22: =IFERROR(F22/G22-1,"") | J22: =IFERROR(F22-G22,"") | K22: =IFERROR(IF(VLOOKUP(C22,CB歷年最高最低價!$A:$F,5,FALSE)="H","🔴新高",IF(VLOOKUP(C22,CB歷年最高最低價!$A:$F,5,FALSE)="L","🟢新低",IF(VLOOKUP(C22,CB歷年最高最低價!$A:$F,5,FALSE)="HL","🔴🟢",""))),"") | L22: =IFERROR(IF(VLOOKUP(C22,CB歷年最高最低價!$A:$F,6,FALSE)="","",VLOOKUP(C22,CB歷年最高最低價!$A:$F,6,FALSE)),"")
B23: 18 | D23: =IFERROR(VLOOKUP(C23,CB歷年最高最低價!$A:$D,2,FALSE),"") | E23: =IFERROR(VLOOKUP(C23,對應表!$A:$B,2,FALSE),"") | F23: =IFERROR(VLOOKUP(C23,CB歷年最高最低價!$A:$D,3,FALSE),"") | G23: =IFERROR(VLOOKUP(C23,CB歷年最高最低價!$A:$D,4,FALSE),"") | H23: =IFERROR(F23/G23,"") | I23: =IFERROR(F23/G23-1,"") | J23: =IFERROR(F23-G23,"") | K23: =IFERROR(IF(VLOOKUP(C23,CB歷年最高最低價!$A:$F,5,FALSE)="H","🔴新高",IF(VLOOKUP(C23,CB歷年最高最低價!$A:$F,5,FALSE)="L","🟢新低",IF(VLOOKUP(C23,CB歷年最高最低價!$A:$F,5,FALSE)="HL","🔴🟢",""))),"") | L23: =IFERROR(IF(VLOOKUP(C23,CB歷年最高最低價!$A:$F,6,FALSE)="","",VLOOKUP(C23,CB歷年最高最低價!$A:$F,6,FALSE)),"")
B24: 19 | D24: =IFERROR(VLOOKUP(C24,CB歷年最高最低價!$A:$D,2,FALSE),"") | E24: =IFERROR(VLOOKUP(C24,對應表!$A:$B,2,FALSE),"") | F24: =IFERROR(VLOOKUP(C24,CB歷年最高最低價!$A:$D,3,FALSE),"") | G24: =IFERROR(VLOOKUP(C24,CB歷年最高最低價!$A:$D,4,FALSE),"") | H24: =IFERROR(F24/G24,"") | I24: =IFERROR(F24/G24-1,"") | J24: =IFERROR(F24-G24,"") | K24: =IFERROR(IF(VLOOKUP(C24,CB歷年最高最低價!$A:$F,5,FALSE)="H","🔴新高",IF(VLOOKUP(C24,CB歷年最高最低價!$A:$F,5,FALSE)="L","🟢新低",IF(VLOOKUP(C24,CB歷年最高最低價!$A:$F,5,FALSE)="HL","🔴🟢",""))),"") | L24: =IFERROR(IF(VLOOKUP(C24,CB歷年最高最低價!$A:$F,6,FALSE)="","",VLOOKUP(C24,CB歷年最高最低價!$A:$F,6,FALSE)),"")
... B35: 30 | D35: =IFERROR(VLOOKUP(C35,CB歷年最高最低價!$A:$D,2,FALSE),"") | E35: =IFERROR(VLOOKUP(C35,對應表!$A:$B,2,FALSE),"") | F35: =IFERROR(VLOOKUP(C35,CB歷年最高最低價!$A:$D,3,FALSE),"") | G35: =IFERROR(VLOOKUP(C35,CB歷年最高最低價!$A:$D,4,FALSE),"") | H35: =IFERROR(F35/G35,"") | I35: =IFERROR(F35/G35-1,"") | J35: =IFERROR(F35-G35,"") | K35: =IFERROR(IF(VLOOKUP(C35,CB歷年最高最低價!$A:$F,5,FALSE)="H","🔴新高",IF(VLOOKUP(C35,CB歷年最高最低價!$A:$F,5,FALSE)="L","🟢新低",IF(VLOOKUP(C35,CB歷年最高最低價!$A:$F,5,FALSE)="HL","🔴🟢",""))),"") | L35: =IFERROR(IF(VLOOKUP(C35,CB歷年最高最低價!$A:$F,6,FALSE)="","",VLOOKUP(C35,CB歷年最高最低價!$A:$F,6,FALSE)),"")
B36: 31 | D36: =IFERROR(VLOOKUP(C36,CB歷年最高最低價!$A:$F,2,FALSE),"") | E36: =IFERROR(VLOOKUP(C36,對應表!$A:$B,2,FALSE),"") | F36: =IFERROR(VLOOKUP(C36,CB歷年最高最低價!$A:$F,3,FALSE),"") | G36: =IFERROR(VLOOKUP(C36,CB歷年最高最低價!$A:$F,4,FALSE),"") | H36: =IFERROR(F36/G36,"") | I36: =IFERROR(F36/G36-1,"") | J36: =IFERROR(F36-G36,"") | K36: =IFERROR(IF(VLOOKUP(C36,CB歷年最高最低價!$A:$F,5,FALSE)="H","新高",IF(VLOOKUP(C36,CB歷年最高最低價!$A:$F,5,FALSE)="L","新低",IF(VLOOKUP(C36,CB歷年最高最低價!$A:$F,5,FALSE)="HL","高低",""))),"") | L36: =IFERROR(IF(VLOOKUP(C36,CB歷年最高最低價!$A:$F,6,FALSE)="","",VLOOKUP(C36,CB歷年最高最低價!$A:$F,6,FALSE)),"")
B37: 32 | D37: =IFERROR(VLOOKUP(C37,CB歷年最高最低價!$A:$F,2,FALSE),"") | E37: =IFERROR(VLOOKUP(C37,對應表!$A:$B,2,FALSE),"") | F37: =IFERROR(VLOOKUP(C37,CB歷年最高最低價!$A:$F,3,FALSE),"") | G37: =IFERROR(VLOOKUP(C37,CB歷年最高最低價!$A:$F,4,FALSE),"") | H37: =IFERROR(F37/G37,"") | I37: =IFERROR(F37/G37-1,"") | J37: =IFERROR(F37-G37,"") | K37: =IFERROR(IF(VLOOKUP(C37,CB歷年最高最低價!$A:$F,5,FALSE)="H","新高",IF(VLOOKUP(C37,CB歷年最高最低價!$A:$F,5,FALSE)="L","新低",IF(VLOOKUP(C37,CB歷年最高最低價!$A:$F,5,FALSE)="HL","高低",""))),"") | L37: =IFERROR(IF(VLOOKUP(C37,CB歷年最高最低價!$A:$F,6,FALSE)="","",VLOOKUP(C37,CB歷年最高最低價!$A:$F,6,FALSE)),"")
B38: 33 | D38: =IFERROR(VLOOKUP(C38,CB歷年最高最低價!$A:$F,2,FALSE),"") | E38: =IFERROR(VLOOKUP(C38,對應表!$A:$B,2,FALSE),"") | F38: =IFERROR(VLOOKUP(C38,CB歷年最高最低價!$A:$F,3,FALSE),"") | G38: =IFERROR(VLOOKUP(C38,CB歷年最高最低價!$A:$F,4,FALSE),"") | H38: =IFERROR(F38/G38,"") | I38: =IFERROR(F38/G38-1,"") | J38: =IFERROR(F38-G38,"") | K38: =IFERROR(IF(VLOOKUP(C38,CB歷年最高最低價!$A:$F,5,FALSE)="H","新高",IF(VLOOKUP(C38,CB歷年最高最低價!$A:$F,5,FALSE)="L","新低",IF(VLOOKUP(C38,CB歷年最高最低價!$A:$F,5,FALSE)="HL","高低",""))),"") | L38: =IFERROR(IF(VLOOKUP(C38,CB歷年最高最低價!$A:$F,6,FALSE)="","",VLOOKUP(C38,CB歷年最高最低價!$A:$F,6,FALSE)),"")
B39: 34 | D39: =IFERROR(VLOOKUP(C39,CB歷年最高最低價!$A:$F,2,FALSE),"") | E39: =IFERROR(VLOOKUP(C39,對應表!$A:$B,2,FALSE),"") | F39: =IFERROR(VLOOKUP(C39,CB歷年最高最低價!$A:$F,3,FALSE),"") | G39: =IFERROR(VLOOKUP(C39,CB歷年最高最低價!$A:$F,4,FALSE),"") | H39: =IFERROR(F39/G39,"") | I39: =IFERROR(F39/G39-1,"") | J39: =IFERROR(F39-G39,"") | K39: =IFERROR(IF(VLOOKUP(C39,CB歷年最高最低價!$A:$F,5,FALSE)="H","新高",IF(VLOOKUP(C39,CB歷年最高最低價!$A:$F,5,FALSE)="L","新低",IF(VLOOKUP(C39,CB歷年最高最低價!$A:$F,5,FALSE)="HL","高低",""))),"") | L39: =IFERROR(IF(VLOOKUP(C39,CB歷年最高最低價!$A:$F,6,FALSE)="","",VLOOKUP(C39,CB歷年最高最低價!$A:$F,6,FALSE)),"")
B40: 35 | D40: =IFERROR(VLOOKUP(C40,CB歷年最高最低價!$A:$F,2,FALSE),"") | E40: =IFERROR(VLOOKUP(C40,對應表!$A:$B,2,FALSE),"") | F40: =IFERROR(VLOOKUP(C40,CB歷年最高最低價!$A:$F,3,FALSE),"") | G40: =IFERROR(VLOOKUP(C40,CB歷年最高最低價!$A:$F,4,FALSE),"") | H40: =IFERROR(F40/G40,"") | I40: =IFERROR(F40/G40-1,"") | J40: =IFERROR(F40-G40,"") | K40: =IFERROR(IF(VLOOKUP(C40,CB歷年最高最低價!$A:$F,5,FALSE)="H","新高",IF(VLOOKUP(C40,CB歷年最高最低價!$A:$F,5,FALSE)="L","新低",IF(VLOOKUP(C40,CB歷年最高最低價!$A:$F,5,FALSE)="HL","高低",""))),"") | L40: =IFERROR(IF(VLOOKUP(C40,CB歷年最高最低價!$A:$F,6,FALSE)="","",VLOOKUP(C40,CB歷年最高最低價!$A:$F,6,FALSE)),"")
B41: 36 | D41: =IFERROR(VLOOKUP(C41,CB歷年最高最低價!$A:$F,2,FALSE),"") | E41: =IFERROR(VLOOKUP(C41,對應表!$A:$B,2,FALSE),"") | F41: =IFERROR(VLOOKUP(C41,CB歷年最高最低價!$A:$F,3,FALSE),"") | G41: =IFERROR(VLOOKUP(C41,CB歷年最高最低價!$A:$F,4,FALSE),"") | H41: =IFERROR(F41/G41,"") | I41: =IFERROR(F41/G41-1,"") | J41: =IFERROR(F41-G41,"") | K41: =IFERROR(IF(VLOOKUP(C41,CB歷年最高最低價!$A:$F,5,FALSE)="H","新高",IF(VLOOKUP(C41,CB歷年最高最低價!$A:$F,5,FALSE)="L","新低",IF(VLOOKUP(C41,CB歷年最高最低價!$A:$F,5,FALSE)="HL","高低",""))),"") | L41: =IFERROR(IF(VLOOKUP(C41,CB歷年最高最低價!$A:$F,6,FALSE)="","",VLOOKUP(C41,CB歷年最高最低價!$A:$F,6,FALSE)),"")
B42: 37 | D42: =IFERROR(VLOOKUP(C42,CB歷年最高最低價!$A:$F,2,FALSE),"") | E42: =IFERROR(VLOOKUP(C42,對應表!$A:$B,2,FALSE),"") | F42: =IFERROR(VLOOKUP(C42,CB歷年最高最低價!$A:$F,3,FALSE),"") | G42: =IFERROR(VLOOKUP(C42,CB歷年最高最低價!$A:$F,4,FALSE),"") | H42: =IFERROR(F42/G42,"") | I42: =IFERROR(F42/G42-1,"") | J42: =IFERROR(F42-G42,"") | K42: =IFERROR(IF(VLOOKUP(C42,CB歷年最高最低價!$A:$F,5,FALSE)="H","新高",IF(VLOOKUP(C42,CB歷年最高最低價!$A:$F,5,FALSE)="L","新低",IF(VLOOKUP(C42,CB歷年最高最低價!$A:$F,5,FALSE)="HL","高低",""))),"") | L42: =IFERROR(IF(VLOOKUP(C42,CB歷年最高最低價!$A:$F,6,FALSE)="","",VLOOKUP(C42,CB歷年最高最低價!$A:$F,6,FALSE)),"")
B43: 38 | D43: =IFERROR(VLOOKUP(C43,CB歷年最高最低價!$A:$F,2,FALSE),"") | E43: =IFERROR(VLOOKUP(C43,對應表!$A:$B,2,FALSE),"") | F43: =IFERROR(VLOOKUP(C43,CB歷年最高最低價!$A:$F,3,FALSE),"") | G43: =IFERROR(VLOOKUP(C43,CB歷年最高最低價!$A:$F,4,FALSE),"") | H43: =IFERROR(F43/G43,"") | I43: =IFERROR(F43/G43-1,"") | J43: =IFERROR(F43-G43,"") | K43: =IFERROR(IF(VLOOKUP(C43,CB歷年最高最低價!$A:$F,5,FALSE)="H","新高",IF(VLOOKUP(C43,CB歷年最高最低價!$A:$F,5,FALSE)="L","新低",IF(VLOOKUP(C43,CB歷年最高最低價!$A:$F,5,FALSE)="HL","高低",""))),"") | L43: =IFERROR(IF(VLOOKUP(C43,CB歷年最高最低價!$A:$F,6,FALSE)="","",VLOOKUP(C43,CB歷年最高最低價!$A:$F,6,FALSE)),"")
B44: 39 | D44: =IFERROR(VLOOKUP(C44,CB歷年最高最低價!$A:$F,2,FALSE),"") | E44: =IFERROR(VLOOKUP(C44,對應表!$A:$B,2,FALSE),"") | F44: =IFERROR(VLOOKUP(C44,CB歷年最高最低價!$A:$F,3,FALSE),"") | G44: =IFERROR(VLOOKUP(C44,CB歷年最高最低價!$A:$F,4,FALSE),"") | H44: =IFERROR(F44/G44,"") | I44: =IFERROR(F44/G44-1,"") | J44: =IFERROR(F44-G44,"") | K44: =IFERROR(IF(VLOOKUP(C44,CB歷年最高最低價!$A:$F,5,FALSE)="H","新高",IF(VLOOKUP(C44,CB歷年最高最低價!$A:$F,5,FALSE)="L","新低",IF(VLOOKUP(C44,CB歷年最高最低價!$A:$F,5,FALSE)="HL","高低",""))),"") | L44: =IFERROR(IF(VLOOKUP(C44,CB歷年最高最低價!$A:$F,6,FALSE)="","",VLOOKUP(C44,CB歷年最高最低價!$A:$F,6,FALSE)),"")
B45: 40 | D45: =IFERROR(VLOOKUP(C45,CB歷年最高最低價!$A:$F,2,FALSE),"") | E45: =IFERROR(VLOOKUP(C45,對應表!$A:$B,2,FALSE),"") | F45: =IFERROR(VLOOKUP(C45,CB歷年最高最低價!$A:$F,3,FALSE),"") | G45: =IFERROR(VLOOKUP(C45,CB歷年最高最低價!$A:$F,4,FALSE),"") | H45: =IFERROR(F45/G45,"") | I45: =IFERROR(F45/G45-1,"") | J45: =IFERROR(F45-G45,"") | K45: =IFERROR(IF(VLOOKUP(C45,CB歷年最高最低價!$A:$F,5,FALSE)="H","新高",IF(VLOOKUP(C45,CB歷年最高最低價!$A:$F,5,FALSE)="L","新低",IF(VLOOKUP(C45,CB歷年最高最低價!$A:$F,5,FALSE)="HL","高低",""))),"") | L45: =IFERROR(IF(VLOOKUP(C45,CB歷年最高最低價!$A:$F,6,FALSE)="","",VLOOKUP(C45,CB歷年最高最低價!$A:$F,6,FALSE)),"")
B46: 41 | D46: =IFERROR(VLOOKUP(C46,CB歷年最高最低價!$A:$F,2,FALSE),"") | E46: =IFERROR(VLOOKUP(C46,對應表!$A:$B,2,FALSE),"") | F46: =IFERROR(VLOOKUP(C46,CB歷年最高最低價!$A:$F,3,FALSE),"") | G46: =IFERROR(VLOOKUP(C46,CB歷年最高最低價!$A:$F,4,FALSE),"") | H46: =IFERROR(F46/G46,"") | I46: =IFERROR(F46/G46-1,"") | J46: =IFERROR(F46-G46,"") | K46: =IFERROR(IF(VLOOKUP(C46,CB歷年最高最低價!$A:$F,5,FALSE)="H","新高",IF(VLOOKUP(C46,CB歷年最高最低價!$A:$F,5,FALSE)="L","新低",IF(VLOOKUP(C46,CB歷年最高最低價!$A:$F,5,FALSE)="HL","高低",""))),"") | L46: =IFERROR(IF(VLOOKUP(C46,CB歷年最高最低價!$A:$F,6,FALSE)="","",VLOOKUP(C46,CB歷年最高最低價!$A:$F,6,FALSE)),"")
B47: 42 | D47: =IFERROR(VLOOKUP(C47,CB歷年最高最低價!$A:$F,2,FALSE),"") | E47: =IFERROR(VLOOKUP(C47,對應表!$A:$B,2,FALSE),"") | F47: =IFERROR(VLOOKUP(C47,CB歷年最高最低價!$A:$F,3,FALSE),"") | G47: =IFERROR(VLOOKUP(C47,CB歷年最高最低價!$A:$F,4,FALSE),"") | H47: =IFERROR(F47/G47,"") | I47: =IFERROR(F47/G47-1,"") | J47: =IFERROR(F47-G47,"") | K47: =IFERROR(IF(VLOOKUP(C47,CB歷年最高最低價!$A:$F,5,FALSE)="H","新高",IF(VLOOKUP(C47,CB歷年最高最低價!$A:$F,5,FALSE)="L","新低",IF(VLOOKUP(C47,CB歷年最高最低價!$A:$F,5,FALSE)="HL","高低",""))),"") | L47: =IFERROR(IF(VLOOKUP(C47,CB歷年最高最低價!$A:$F,6,FALSE)="","",VLOOKUP(C47,CB歷年最高最低價!$A:$F,6,FALSE)),"")
... B55: 50 | D55: =IFERROR(VLOOKUP(C55,CB歷年最高最低價!$A:$F,2,FALSE),"") | E55: =IFERROR(VLOOKUP(C55,對應表!$A:$B,2,FALSE),"") | F55: =IFERROR(VLOOKUP(C55,CB歷年最高最低價!$A:$F,3,FALSE),"") | G55: =IFERROR(VLOOKUP(C55,CB歷年最高最低價!$A:$F,4,FALSE),"") | H55: =IFERROR(F55/G55,"") | I55: =IFERROR(F55/G55-1,"") | J55: =IFERROR(F55-G55,"") | K55: =IFERROR(IF(VLOOKUP(C55,CB歷年最高最低價!$A:$F,5,FALSE)="H","新高",IF(VLOOKUP(C55,CB歷年最高最低價!$A:$F,5,FALSE)="L","新低",IF(VLOOKUP(C55,CB歷年最高最低價!$A:$F,5,FALSE)="HL","高低",""))),"") | L55: =IFERROR(IF(VLOOKUP(C55,CB歷年最高最低價!$A:$F,6,FALSE)="","",VLOOKUP(C55,CB歷年最高最低價!$A:$F,6,FALSE)),"")
B57: 📊 平均值 | F57: =IFERROR(AVERAGE(F6:F55),"") | G57: =IFERROR(AVERAGE(G6:G55),"") | H57: =IFERROR(AVERAGE(H6:H55),"") | I57: =IFERROR(AVERAGE(I6:I55),"") | J57: =IFERROR(AVERAGE(J6:J55),"")
B59: 📌 使用說明
B60: 1. 在 C 欄黃色區輸入 CB 代號(5~6 碼),可跨公司自由組合最多 50 檔
B61: 2. 名稱、股票代號、高低價、振幅會自動帶出
...

Sheet 對應表
A1: CB代號 | B1: 股票代號 | C1: 命中序
A2: 11011 | B2: 1101 | C2: =IF(B2='🎯 一鍵查詢'!$C$5,COUNTIF($B$2:B2,'🎯 一鍵查詢'!$C$5),"")
A3: 12101 | B3: 1210 | C3: =IF(B3='🎯 一鍵查詢'!$C$5,COUNTIF($B$2:B3,'🎯 一鍵查詢'!$C$5),"")
A4: 12161 | B4: 1216 | C4: =IF(B4='🎯 一鍵查詢'!$C$5,COUNTIF($B$2:B4,'🎯 一鍵查詢'!$C$5),"")
A5: 12171 | B5: 1217 | C5: =IF(B5='🎯 一鍵查詢'!$C$5,COUNTIF($B$2:B5,'🎯 一鍵查詢'!$C$5),"")
A6: 12172 | B6: 1217 | C6: =IF(B6='🎯 一鍵查詢'!$C$5,COUNTIF($B$2:B6,'🎯 一鍵查詢'!$C$5),"")
A7: 12173 | B7: 1217 | C7: =IF(B7='🎯 一鍵查詢'!$C$5,COUNTIF($B$2:B7,'🎯 一鍵查詢'!$C$5),"")
A8: 12181 | B8: 1218 | C8: =IF(B8='🎯 一鍵查詢'!$C$5,COUNTIF($B$2:B8,'🎯 一鍵查詢'!$C$5),"")
A9: 12251 | B9: 1225 | C9: =IF(B9='🎯 一鍵查詢'!$C$5,COUNTIF($B$2:B9,'🎯 一鍵查詢'!$C$5),"")
A10: 12561 | B10: 1256 | C10: =IF(B10='🎯 一鍵查詢'!$C$5,COUNTIF($B$2:B10,'🎯 一鍵查詢'!$C$5),"")
A11: 12581 | B11: 1258 | C11: =IF(B11='🎯 一鍵查詢'!$C$5,COUNTIF($B$2:B11,'🎯 一鍵查詢'!$C$5),"")
A12: 12582 | B12: 1258 | C12: =IF(B12='🎯 一鍵查詢'!$C$5,COUNTIF($B$2:B12,'🎯 一鍵查詢'!$C$5),"")
A13: 13121 | B13: 1312 | C13: =IF(B13='🎯 一鍵查詢'!$C$5,COUNTIF($B$2:B13,'🎯 一鍵查詢'!$C$5),"")
... A2297: 84624 | B2297: 8462 | C2297: =IF(B2297='🎯 一鍵查詢'!$C$5,COUNTIF($B$2:B2297,'🎯 一鍵查詢'!$C$5),"")

Sheet CB歷年最高最低價
A1: 代號 | B1: 名稱 | C1: 掛牌最高 | D1: 掛牌最低 | E1: 異動 | F1: 月變化%
A2: 11011 | B2: 台泥一永 | C2: 108.1 | D2: 94.4
A3: 12101 | B3: 大成一 | C3: 127 | D3: 72.5
A4: 12161 | B4: 統一一 | C4: 106.75 | D4: 91.2
A5: 12171 | B5: 愛之味一 | C5: 123 | D5: 100
A6: 12172 | B6: 愛之味二 | C6: 112 | D6: 89
A7: 12173 | B7: 愛之味三 | C7: 105 | D7: 99.6
A8: 12181 | B8: 泰山一 | C8: 109.9 | D8: 99
A9: 12251 | B9: 福脂一 | C9: 233 | D9: 101
A10: 12561 | B10: 鮮活果汁一KY | C10: 109 | D10: 94.55 | E10: H | F10: 0.048076923
A11: 12581 | B11: 其祥一KY | C11: 124.25 | D11: 99.1
A12: 12582 | B12: 其祥二KY | C12: 101.3 | D12: 76.2
A13: 13121 | B13: 國喬一 | C13: 171 | D13: 90
A14: 13161 | B14: 上曜一 | C14: 122 | D14: 99.65
A15: 13162 | B15: 上曜二 | C15: 177 | D15: 104
A16: 13163 | B16: 上曜三 | C16: 117.95 | D16: 99.6
A17: 13164 | B17: 上曜四 | C17: 189 | D17: 99.5
A18: 13165 | B18: 上曜五 | C18: 232 | D18: 99.6
A19: 13166 | B19: 上曜六 | C19: 125.5 | D19: 102.8
A20: 13191 | B20: 東陽一 | C20: 115 | D20: 95.4
A21: 13361 | B21: 台翰一 | C21: 116 | D21: 101.1
A22: 13371 | B22: 再生一 | C22: 120.5 | D22: 82.95
... A47: 14722 | B47: 三洋實業二 | C47: 110.3 | D47: 103.05
A48: 14723 | B48: 三洋實業三 | C48: 100 | D48: 94.25 | E48: H | F48: 0.0055304173
A49: 14741 | B49: 弘裕一 | C49: 125 | D49: 100
A50: 14742 | B50: 弘裕二 | C50: 117 | D50: 96
A51: 14743 | B51: 弘裕三 | C51: 99.95 | D51: 87.6 | E51: L | F51: -0.02122905
A52: 14771 | B52: 聚陽一 | C52: 386 | D52: 110
A53: 14772 | B53: 聚陽二 | C53: 292 | D53: 100
A54: 14773 | B54: 聚陽三 | C54: 495 | D54: 106.5
A55: 14774 | B55: 聚陽四 | C55: 401 | D55: 106.2
A56: 15043 | B56: 東元三 | C56: 167 | D56: 99.05
A57: 15061 | B57: 正道一 | C57: 121 | D57: 96.95
A58: 15131 | B58: 中興電一 | C58: 213 | D58: 101
A59: 15132 | B59: 中興電二 | C59: 231 | D59: 106
A60: 15141 | B60: 亞力一 | C60: 276 | D60: 103.8
A61: 15142 | B61: 亞力二 | C61: 148 | D61: 99.45 | E61: H | F61: 0.059792338
A62: 15151 | B62: 力山一 | C62: 131 | D62: 122
A63: 15221 | B63: 堤維西一 | C63: 142 | D63: 92
A64: 15241 | B64: 耿鼎一 | C64: 195 | D64: 103.2
...
